<?xml version="1.0" encoding="utf-8"?>
<!-- This URDF was automatically created by SolidWorks to URDF Exporter! Originally created by Stephen Brawner (brawner@gmail.com) 
     Commit Version: 1.6.0-4-g7f85cfe  Build Version: 1.6.7995.38578
     For more information, please see http://wiki.ros.org/sw_urdf_exporter -->
<robot
  name="dexter_arm">
  <link
    name="base_link">
    <inertial>
      <origin
        xyz="1.94289029309402E-16 -1.17267306976032E-15 0.336691106271961"
        rpy="0 0 0" />
      <mass
        value="1.50541140238431" />
      <inertia
        ixx="0.015557818570861"
        ixy="6.84623852621616E-12"
        ixz="3.83456530151513E-19"
        iyy="0.0180203504414457"
        iyz="5.38593319905951E-17"
        izz="0.00261529849461049" />
    </inertial>
    <visual>
      <origin
        xyz="0 0 0"
        rpy="0 0 0" />
      <geometry>
        <mesh
          filename="package://dexter_arm_description/meshes/base_link.STL" />
      </geometry>
      <material
        name="">
        <color
          rgba="0.792156862745098 0.819607843137255 0.933333333333333 1" />
      </material>
    </visual>
    <collision>
      <origin
        xyz="0 0 0"
        rpy="0 0 0" />
      <geometry>
        <mesh
          filename="package://dexter_arm_description/meshes/base_link.STL" />
      </geometry>
    </collision>
  </link>
  <link
    name="l1l">
    <inertial>
      <origin
        xyz="-2.06768076455033E-05 -3.7470027081099E-16 0.020318702946937"
        rpy="0 0 0" />
      <mass
        value="0.0412610106656879" />
      <inertia
        ixx="6.45452263055138E-06"
        ixy="3.97873238125421E-21"
        ixz="-5.67173895647604E-10"
        iyy="1.08529418395194E-05"
        iyz="-2.17709921074147E-21"
        izz="8.35698735982534E-06" />
    </inertial>
    <visual>
      <origin
        xyz="0 0 0"
        rpy="0 0 0" />
      <geometry>
        <mesh
          filename="package://dexter_arm_description/meshes/l1l.STL" />
      </geometry>
      <material
        name="">
        <color
          rgba="1 1 1 1" />
      </material>
    </visual>
    <collision>
      <origin
        xyz="0 0 0"
        rpy="0 0 0" />
      <geometry>
        <mesh
          filename="package://dexter_arm_description/meshes/l1l.STL" />
      </geometry>
    </collision>
  </link>
  <joint
    name="j1l"
    type="revolute">
    <origin
      xyz="-0.185 0 0.5347"
      rpy="3.14159265358979 0 0" />
    <parent
      link="base_link" />
    <child
      link="l1l" />
    <axis
      xyz="0 0 1" />
    <limit
      lower="-1.57"
      upper="1.57"
      effort="3.43"
      velocity="5" />
  </joint>
  <link
    name="l2l">
    <inertial>
      <origin
        xyz="0.041999999999998 -2.59901822285968E-12 -4.31399360678597E-12"
        rpy="0 0 0" />
      <mass
        value="0.0412639771770678" />
      <inertia
        ixx="2.03861872352237E-05"
        ixy="1.63053089891251E-16"
        ixz="-1.24803181399013E-19"
        iyy="2.30212674355658E-05"
        iyz="4.89586440745353E-20"
        izz="8.54833447441497E-06" />
    </inertial>
    <visual>
      <origin
        xyz="0 0 0"
        rpy="0 0 0" />
      <geometry>
        <mesh
          filename="package://dexter_arm_description/meshes/l2l.STL" />
      </geometry>
      <material
        name="">
        <color
          rgba="1 1 1 1" />
      </material>
    </visual>
    <collision>
      <origin
        xyz="0 0 0"
        rpy="0 0 0" />
      <geometry>
        <mesh
          filename="package://dexter_arm_description/meshes/l2l.STL" />
      </geometry>
    </collision>
  </link>
  <joint
    name="j2l"
    type="revolute">
    <origin
      xyz="0 0 0.0340000000000011"
      rpy="0 -1.5707963267949 0" />
    <parent
      link="l1l" />
    <child
      link="l2l" />
    <axis
      xyz="0 0 1" />
    <limit
      lower="-1.57"
      upper="1.57"
      effort="3.43"
      velocity="5" />
  </joint>
  <link
    name="l3l">
    <inertial>
      <origin
        xyz="0.0425000000000001 5.22055315643755E-12 -4.31427116254213E-12"
        rpy="0 0 0" />
      <mass
        value="0.0895845826981461" />
      <inertia
        ixx="1.79494942674491E-05"
        ixy="-6.04671250972153E-16"
        ixz="-1.13434779133394E-09"
        iyy="2.28721177257845E-05"
        iyz="-1.7861308915074E-19"
        izz="1.35465501240485E-05" />
    </inertial>
    <visual>
      <origin
        xyz="0 0 0"
        rpy="0 0 0" />
      <geometry>
        <mesh
          filename="package://dexter_arm_description/meshes/l3l.STL" />
      </geometry>
      <material
        name="">
        <color
          rgba="1 1 1 1" />
      </material>
    </visual>
    <collision>
      <origin
        xyz="0 0 0"
        rpy="0 0 0" />
      <geometry>
        <mesh
          filename="package://dexter_arm_description/meshes/l3l.STL" />
      </geometry>
    </collision>
  </link>
  <joint
    name="j3l"
    type="revolute">
    <origin
      xyz="0.083999999999998 0 0"
      rpy="0 0 0" />
    <parent
      link="l2l" />
    <child
      link="l3l" />
    <axis
      xyz="0 0 1" />
    <limit
      lower="-1.57"
      upper="1.57"
      effort="3.43"
      velocity="5" />
  </joint>
  <link
    name="l4l">
    <inertial>
      <origin
        xyz="0.0420000000000001 -3.82788245545385E-12 -4.31488178520567E-12"
        rpy="0 0 0" />
      <mass
        value="0.0412639771770679" />
      <inertia
        ixx="2.03861872352237E-05"
        ixy="2.40158108021555E-16"
        ixz="-3.21447378747586E-20"
        iyy="2.30212674355658E-05"
        iyz="1.52556101057664E-19"
        izz="8.54833447441497E-06" />
    </inertial>
    <visual>
      <origin
        xyz="0 0 0"
        rpy="0 0 0" />
      <geometry>
        <mesh
          filename="package://dexter_arm_description/meshes/l4l.STL" />
      </geometry>
      <material
        name="">
        <color
          rgba="1 1 1 1" />
      </material>
    </visual>
    <collision>
      <origin
        xyz="0 0 0"
        rpy="0 0 0" />
      <geometry>
        <mesh
          filename="package://dexter_arm_description/meshes/l4l.STL" />
      </geometry>
    </collision>
  </link>
  <joint
    name="j4l"
    type="revolute">
    <origin
      xyz="0.0850000000000001 0 0"
      rpy="0 0 0" />
    <parent
      link="l3l" />
    <child
      link="l4l" />
    <axis
      xyz="0 0 1" />
    <limit
      lower="-1.57"
      upper="1.57"
      effort="1.5"
      velocity="5" />
  </joint>
  <link
    name="l5l">
    <inertial>
      <origin
        xyz="0.0451157165053799 6.85340035748785E-05 -0.000519380265183611"
        rpy="0 0 0" />
      <mass
        value="0.0877350527785504" />
      <inertia
        ixx="2.15592269641527E-05"
        ixy="-1.08634478618299E-12"
        ixz="-6.61837513500249E-07"
        iyy="4.2127173971068E-05"
        iyz="-2.81945757063296E-12"
        izz="2.98080635390039E-05" />
    </inertial>
    <visual>
      <origin
        xyz="0 0 0"
        rpy="0 0 0" />
      <geometry>
        <mesh
          filename="package://dexter_arm_description/meshes/l5l.STL" />
      </geometry>
      <material
        name="">
        <color
          rgba="1 1 1 1" />
      </material>
    </visual>
    <collision>
      <origin
        xyz="0 0 0"
        rpy="0 0 0" />
      <geometry>
        <mesh
          filename="package://dexter_arm_description/meshes/l5l.STL" />
      </geometry>
    </collision>
  </link>
  <joint
    name="j5l"
    type="revolute">
    <origin
      xyz="0.0840000000000015 0 0"
      rpy="0 0 0" />
    <parent
      link="l4l" />
    <child
      link="l5l" />
    <axis
      xyz="0 0 1" />
    <limit
      lower="-1.57"
      upper="1.57"
      effort="1.5"
      velocity="5" />
  </joint>
  <link
    name="l6l">
    <inertial>
      <origin
        xyz="-0.00476528037739832 -0.000653262779644108 0.0369292064765206"
        rpy="0 0 0" />
      <mass
        value="0.160590985030217" />
      <inertia
        ixx="5.06987158754222E-05"
        ixy="6.78041755969928E-10"
        ixz="1.12451618614082E-06"
        iyy="0.000111016162710577"
        iyz="-1.51064931043486E-10"
        izz="0.000135606227386264" />
    </inertial>
    <visual>
      <origin
        xyz="0 0 0"
        rpy="0 0 0" />
      <geometry>
        <mesh
          filename="package://dexter_arm_description/meshes/l6l.STL" />
      </geometry>
      <material
        name="">
        <color
          rgba="0.792156862745098 0.819607843137255 0.933333333333333 1" />
      </material>
    </visual>
    <collision>
      <origin
        xyz="0 0 0"
        rpy="0 0 0" />
      <geometry>
        <mesh
          filename="package://dexter_arm_description/meshes/l6l.STL" />
      </geometry>
    </collision>
  </link>
  <joint
    name="j6l"
    type="revolute">
    <origin
      xyz="0.100000000000004 0.00011000000184596 -0.0115000000043161"
      rpy="0 1.5707963267949 0" />
    <parent
      link="l5l" />
    <child
      link="l6l" />
    <axis
      xyz="0 0 -1" />
    <limit
      lower="-3.14"
      upper="3.14"
      effort="1.5"
      velocity="5" />
  </joint>
  <link
    name="l7l1">
    <inertial>
      <origin
        xyz="-0.0130590486725677 -0.0655739671662708 0.0299703503590698"
        rpy="0 0 0" />
      <mass
        value="0.0508689051828396" />
      <inertia
        ixx="2.93394596393009E-05"
        ixy="-4.66576010064367E-06"
        ixz="3.1482012642844E-06"
        iyy="1.89128491053784E-05"
        iyz="5.01575897640309E-06"
        izz="2.44707666408611E-05" />
    </inertial>
    <visual>
      <origin
        xyz="0 0 0"
        rpy="0 0 0" />
      <geometry>
        <mesh
          filename="package://dexter_arm_description/meshes/l7l1.STL" />
      </geometry>
      <material
        name="">
        <color
          rgba="0.96078431372549 0.96078431372549 0.964705882352941 1" />
      </material>
    </visual>
    <collision>
      <origin
        xyz="0 0 0"
        rpy="0 0 0" />
      <geometry>
        <mesh
          filename="package://dexter_arm_description/meshes/l7l1.STL" />
      </geometry>
    </collision>
  </link>
  <joint
    name="j7l1"
    type="prismatic">
    <origin
      xyz="-0.00031015564213932 -0.0334996810602779 0.024487500081954"
      rpy="-1.5707963267949 0 0" />
    <parent
      link="l6l" />
    <child
      link="l7l1" />
    <axis
      xyz="1 0 0" />
    <limit
      lower="0.00"
      upper="-0.025"
      effort="0"
      velocity="0" />
  </joint>
  <link
    name="l7l2">
    <inertial>
      <origin
        xyz="-0.0130590486725638 -0.0655739671662711 0.0299703503605255"
        rpy="0 0 0" />
      <mass
        value="0.0508689051828397" />
      <inertia
        ixx="2.93394596393009E-05"
        ixy="-4.66576010064375E-06"
        ixz="3.14820126428442E-06"
        iyy="1.89128491053785E-05"
        iyz="5.01575897640308E-06"
        izz="2.44707666408611E-05" />
    </inertial>
    <visual>
      <origin
        xyz="0 0 0"
        rpy="0 0 0" />
      <geometry>
        <mesh
          filename="package://dexter_arm_description/meshes/l7l2.STL" />
      </geometry>
      <material
        name="">
        <color
          rgba="0.96078431372549 0.96078431372549 0.964705882352941 1" />
      </material>
    </visual>
    <collision>
      <origin
        xyz="0 0 0"
        rpy="0 0 0" />
      <geometry>
        <mesh
          filename="package://dexter_arm_description/meshes/l7l2.STL" />
      </geometry>
    </collision>
  </link>
  <joint
    name="j7l2"
    type="prismatic">
    <origin
      xyz="0.0138251055330376 0.0320003186418183 0.0244125000819536"
      rpy="-1.5707963267949 0 3.14159265358979" />
    <parent
      link="l6l" />
    <child
      link="l7l2" />
    <axis
      xyz="-1 0 0" />
    <limit
      lower="-0.025"
      upper="0.0"
      effort="0"
      velocity="0" />
  </joint>
  <link
    name="l1r">
    <inertial>
      <origin
        xyz="-2.06768076423253E-05 1.73472347597681E-16 0.0203187029469341"
        rpy="0 0 0" />
      <mass
        value="0.0412610106656878" />
      <inertia
        ixx="6.45452263055136E-06"
        ixy="-1.27336023491028E-21"
        ixz="-5.67173895653783E-10"
        iyy="1.08529418395194E-05"
        iyz="-1.17131567321725E-20"
        izz="8.35698735982531E-06" />
    </inertial>
    <visual>
      <origin
        xyz="0 0 0"
        rpy="0 0 0" />
      <geometry>
        <mesh
          filename="package://dexter_arm_description/meshes/l1r.STL" />
      </geometry>
      <material
        name="">
        <color
          rgba="1 1 1 1" />
      </material>
    </visual>
    <collision>
      <origin
        xyz="0 0 0"
        rpy="0 0 0" />
      <geometry>
        <mesh
          filename="package://dexter_arm_description/meshes/l1r.STL" />
      </geometry>
    </collision>
  </link>
  <joint
    name="j1r"
    type="revolute">
    <origin
      xyz="0.185 0 0.534699999999999"
      rpy="-3.14159265358979 0 0" />
    <parent
      link="base_link" />
    <child
      link="l1r" />
    <axis
      xyz="0 0 1" />
    <limit
      lower="-1.57"
      upper="1.57"
      effort="3.43"
      velocity="5" />
  </joint>
  <link
    name="l2r">
    <inertial>
      <origin
        xyz="0.0420000000000003 6.89094614703123E-13 4.31335522854681E-12"
        rpy="0 0 0" />
      <mass
        value="0.0412639771770678" />
      <inertia
        ixx="2.03861872352237E-05"
        ixy="-4.32483061785773E-17"
        ixz="2.35202404428686E-20"
        iyy="2.30212674355658E-05"
        iyz="4.48398426029756E-20"
        izz="8.54833447441498E-06" />
    </inertial>
    <visual>
      <origin
        xyz="0 0 0"
        rpy="0 0 0" />
      <geometry>
        <mesh
          filename="package://dexter_arm_description/meshes/l2r.STL" />
      </geometry>
      <material
        name="">
        <color
          rgba="1 1 1 1" />
      </material>
    </visual>
    <collision>
      <origin
        xyz="0 0 0"
        rpy="0 0 0" />
      <geometry>
        <mesh
          filename="package://dexter_arm_description/meshes/l2r.STL" />
      </geometry>
    </collision>
  </link>
  <joint
    name="j2r"
    type="revolute">
    <origin
      xyz="0 0 0.0339999999999996"
      rpy="3.14159265358979 -1.5707963267949 0" />
    <parent
      link="l1r" />
    <child
      link="l2r" />
    <axis
      xyz="0 0 -1" />
    <limit
      lower="-1.57"
      upper="1.57"
      effort="3.43"
      velocity="5" />
  </joint>
  <link
    name="l3r">
    <inertial>
      <origin
        xyz="0.042499999999999 -9.64506252643105E-15 4.31646385301576E-12"
        rpy="0 0 0" />
      <mass
        value="0.0895845826981461" />
      <inertia
        ixx="1.79494942674491E-05"
        ixy="-2.38009674149187E-20"
        ixz="1.13434779130171E-09"
        iyy="2.28721177257846E-05"
        iyz="-1.00376713822626E-20"
        izz="1.35465501240486E-05" />
    </inertial>
    <visual>
      <origin
        xyz="0 0 0"
        rpy="0 0 0" />
      <geometry>
        <mesh
          filename="package://dexter_arm_description/meshes/l3r.STL" />
      </geometry>
      <material
        name="">
        <color
          rgba="1 1 1 1" />
      </material>
    </visual>
    <collision>
      <origin
        xyz="0 0 0"
        rpy="0 0 0" />
      <geometry>
        <mesh
          filename="package://dexter_arm_description/meshes/l3r.STL" />
      </geometry>
    </collision>
  </link>
  <joint
    name="j3r"
    type="revolute">
    <origin
      xyz="0.0840000000000007 0 0"
      rpy="0 0 0" />
    <parent
      link="l2r" />
    <child
      link="l3r" />
    <axis
      xyz="0 0 -1" />
    <limit
      lower="-1.57"
      upper="1.57"
      effort="3.43"
      velocity="5" />
  </joint>
  <link
    name="l4r">
    <inertial>
      <origin
        xyz="0.0419999999999995 -5.86537762803374E-13 4.31464586281294E-12"
        rpy="0 0 0" />
      <mass
        value="0.0412639771770678" />
      <inertia
        ixx="2.03861872352237E-05"
        ixy="4.66903518134811E-17"
        ixz="2.626158100344E-20"
        iyy="2.30212674355658E-05"
        iyz="1.47683200562412E-19"
        izz="8.54833447441498E-06" />
    </inertial>
    <visual>
      <origin
        xyz="0 0 0"
        rpy="0 0 0" />
      <geometry>
        <mesh
          filename="package://dexter_arm_description/meshes/l4r.STL" />
      </geometry>
      <material
        name="">
        <color
          rgba="1 1 1 1" />
      </material>
    </visual>
    <collision>
      <origin
        xyz="0 0 0"
        rpy="0 0 0" />
      <geometry>
        <mesh
          filename="package://dexter_arm_description/meshes/l4r.STL" />
      </geometry>
    </collision>
  </link>
  <joint
    name="j4r"
    type="revolute">
    <origin
      xyz="0.0850000000000011 0 0"
      rpy="0 0 0" />
    <parent
      link="l3r" />
    <child
      link="l4r" />
    <axis
      xyz="0 0 -1" />
    <limit
      lower="-1.57"
      upper="1.57"
      effort="1.5"
      velocity="5" />
  </joint>
  <link
    name="l5r">
    <inertial>
      <origin
        xyz="0.0451157165053795 -6.85340036724255E-05 0.000519380265182653"
        rpy="0 0 0" />
      <mass
        value="0.0877350527785506" />
      <inertia
        ixx="2.15592269641528E-05"
        ixy="1.08634469346835E-12"
        ixz="6.61837513500237E-07"
        iyy="4.21271739710681E-05"
        iyz="-2.81945757187487E-12"
        izz="2.9808063539004E-05" />
    </inertial>
    <visual>
      <origin
        xyz="0 0 0"
        rpy="0 0 0" />
      <geometry>
        <mesh
          filename="package://dexter_arm_description/meshes/l5r.STL" />
      </geometry>
      <material
        name="">
        <color
          rgba="1 1 1 1" />
      </material>
    </visual>
    <collision>
      <origin
        xyz="0 0 0"
        rpy="0 0 0" />
      <geometry>
        <mesh
          filename="package://dexter_arm_description/meshes/l5r.STL" />
      </geometry>
    </collision>
  </link>
  <joint
    name="j5r"
    type="revolute">
    <origin
      xyz="0.083999999999999 0 0"
      rpy="0 0 0" />
    <parent
      link="l4r" />
    <child
      link="l5r" />
    <axis
      xyz="0 0 -1" />
    <limit
      lower="-1.57"
      upper="1.57"
      effort="1.5"
      velocity="5" />
  </joint>
  <link
    name="l6r">
    <inertial>
      <origin
        xyz="-0.00476528037740019 -0.000653262777460334 0.0369292064765232"
        rpy="0 0 0" />
      <mass
        value="0.160590985030217" />
      <inertia
        ixx="5.06987158754221E-05"
        ixy="6.78041755694271E-10"
        ixz="1.12451618614082E-06"
        iyy="0.000111016162710577"
        iyz="-1.5106493104616E-10"
        izz="0.000135606227386264" />
    </inertial>
    <visual>
      <origin
        xyz="0 0 0"
        rpy="0 0 0" />
      <geometry>
        <mesh
          filename="package://dexter_arm_description/meshes/l6r.STL" />
      </geometry>
      <material
        name="">
        <color
          rgba="0.792156862745098 0.819607843137255 0.933333333333333 1" />
      </material>
    </visual>
    <collision>
      <origin
        xyz="0 0 0"
        rpy="0 0 0" />
      <geometry>
        <mesh
          filename="package://dexter_arm_description/meshes/l6r.STL" />
      </geometry>
    </collision>
  </link>
  <joint
    name="j6r"
    type="revolute">
    <origin
      xyz="0.0999999999999998 -0.000110000000436546 0.0115000000043133"
      rpy="0 1.5707963267949 0" />
    <parent
      link="l5r" />
    <child
      link="l6r" />
    <axis
      xyz="0 0 -1" />
    <limit
      lower="-3.14"
      upper="3.14"
      effort="1.5"
      velocity="5" />
  </joint>
  <link
    name="l7r1">
    <inertial>
      <origin
        xyz="-0.0130590486814246 -0.0655739671734152 0.0299703503645945"
        rpy="0 0 0" />
      <mass
        value="0.0508689051689457" />
      <inertia
        ixx="2.93394596236661E-05"
        ixy="-4.66576008817436E-06"
        ixz="3.14820125528345E-06"
        iyy="1.89128490852876E-05"
        iyz="5.01575896892049E-06"
        izz="2.44707666160797E-05" />
    </inertial>
    <visual>
      <origin
        xyz="0 0 0"
        rpy="0 0 0" />
      <geometry>
        <mesh
          filename="package://dexter_arm_description/meshes/l7r1.STL" />
      </geometry>
      <material
        name="">
        <color
          rgba="0.96078431372549 0.96078431372549 0.964705882352941 1" />
      </material>
    </visual>
    <collision>
      <origin
        xyz="0 0 0"
        rpy="0 0 0" />
      <geometry>
        <mesh
          filename="package://dexter_arm_description/meshes/l7r1.STL" />
      </geometry>
    </collision>
  </link>
  <joint
    name="j7r1"
    type="prismatic">
    <origin
      xyz="0.0138251055330352 0.0320003186428659 0.0244125000819573"
      rpy="-1.5707963267949 0 3.14159265358979" />
    <parent
      link="l6r" />
    <child
      link="l7r1" />
    <axis
      xyz="-1 0 0" />
    <limit
      lower="-0.025"
      upper="0.0"
      effort="0"
      velocity="0" />
  </joint>
  <link
    name="l7r2">
    <inertial>
      <origin
        xyz="-0.0130590486725645 -0.0655739671662706 0.0299703503599605"
        rpy="0 0 0" />
      <mass
        value="0.0508689051828396" />
      <inertia
        ixx="2.93394596393009E-05"
        ixy="-4.6657601006438E-06"
        ixz="3.14820126428445E-06"
        iyy="1.89128491053786E-05"
        iyz="5.01575897640307E-06"
        izz="2.44707666408611E-05" />
    </inertial>
    <visual>
      <origin
        xyz="0 0 0"
        rpy="0 0 0" />
      <geometry>
        <mesh
          filename="package://dexter_arm_description/meshes/l7r2.STL" />
      </geometry>
      <material
        name="">
        <color
          rgba="0.96078431372549 0.96078431372549 0.964705882352941 1" />
      </material>
    </visual>
    <collision>
      <origin
        xyz="0 0 0"
        rpy="0 0 0" />
      <geometry>
        <mesh
          filename="package://dexter_arm_description/meshes/l7r2.STL" />
      </geometry>
    </collision>
  </link>
  <joint
    name="j7r2"
    type="prismatic">
    <origin
      xyz="-0.000310155642144982 -0.0334996810589849 0.0244125000819576"
      rpy="-1.5707963267949 0 0" />
    <parent
      link="l6r" />
    <child
      link="l7r2" />
    <axis
      xyz="1 0 0" />
    <limit
      lower="0.00"
      upper="-0.025"
      effort="0"
      velocity="0" />
  </joint>
</robot>
